Workbook

Sheet Backlog List
B2: Backlog List
B3: Backlog ID | C3: Task Title | D3: Task Description
B4: 1001 | C4: Our first Amazing title | D4: This is what we need to do.
B5: 1002 | C5: Another title
B6: 1003 | C6: Third Title
B7: 1004 | C7: Fourth Title
B8: 1005 | C8: Fifth title
B9: 1006
B10: 1007
B11: 1008
B12: 1009
B13: 1010
B14: 1011
B15: 1012
B16: 1013
B17: 1014
B18: 1015
B19: 1016
B20: 1017
... B63: 1060

Sheet Kanban Board
B1: Kanban Board
A2: Sprint backlog
G3: To Do | H3: In Discovery | I3: In Development | J3: In Test | K3: Sign Off | L3: Done
B4: ='Backlog List'!B4 -> 1001 | D4: ='Backlog List'!B5 -> 1002
B5: ='Backlog List'!C4 -> Our first Amazing title | D5: ='Backlog List'!C5 -> Another title
B6: Assignee: Billy | D6: Assignee:
B8: ='Backlog List'!B6 -> 1003 | D8: ='Backlog List'!B7 -> 1004
B9: ='Backlog List'!C6 -> Third Title | D9: ='Backlog List'!C7 -> Fourth Title
B10: Assignee: | D10: Assignee:
B12: ='Backlog List'!B8 -> 1005 | D12: ='Backlog List'!B9 -> 1006
B13: ='Backlog List'!C8 -> Fifth title | D13: ='Backlog List'!C9 -> 0
B14: Assignee: | D14: Assignee:
B16: ='Backlog List'!B10 -> 1007 | D16: ='Backlog List'!B11 -> 1008
B17: ='Backlog List'!C10 -> 0 | D17: ='Backlog List'!C11 -> 0
B18: Assignee: | D18: Assignee:
B20: ='Backlog List'!B12 -> 1009 | D20: ='Backlog List'!B13 -> 1010
B21: ='Backlog List'!C12 -> 0 | D21: ='Backlog List'!C13 -> 0
B22: Assignee: | D22: Assignee:
B24: ='Backlog List'!B14 -> 1011 | D24: ='Backlog List'!B15 -> 1012
B25: ='Backlog List'!C14 -> 0 | D25: ='Backlog List'!C15 -> 0
B26: Assignee: | D26: Assignee:
B28: ='Backlog List'!B16 -> 1013 | D28: ='Backlog List'!B17 -> 1014
B29: ='Backlog List'!C16 -> 0 | D29: ='Backlog List'!C17 -> 0
B30: Assignee: | D30: Assignee:
B32: ='Backlog List'!B18 -> 1015 | D32: ='Backlog List'!B19 -> 1016
B33: ='Backlog List'!C18 -> 0 | D33: ='Backlog List'!C19 -> 0
B34: Assignee: | D34: Assignee:
B36: ='Backlog List'!B20 -> 1017 | D36: ='Backlog List'!B21 -> 1018
B37: ='Backlog List'!C20 -> 0 | D37: ='Backlog List'!C21 -> 0
B38: Assignee: | D38: Assignee:
B40: ='Backlog List'!B22 -> 1019 | D40: ='Backlog List'!B23 -> 1020
B41: ='Backlog List'!C22 -> 0 | D41: ='Backlog List'!C23 -> 0
B42: Assignee: | D42: Assignee:
B44: ='Backlog List'!B24 -> 1021 | D44: ='Backlog List'!B25 -> 1022
B45: ='Backlog List'!C24 -> 0 | D45: ='Backlog List'!C25 -> 0
B46: Assignee: | D46: Assignee:
B48: ='Backlog List'!B26 -> 1023 | D48: ='Backlog List'!B27 -> 1024
B49: ='Backlog List'!C26 -> 0 | D49: ='Backlog List'!C27 -> 0
B50: Assignee: | D50: Assignee:
B52: ='Backlog List'!B28 -> 1025 | D52: ='Backlog List'!B29 -> 1026
...
